Workbook

Sheet Overdue Submissions
A1: IntelliBI — Overdue Assignment Submissions Report
A2: Date: 05-Oct-2026 (Monday) | Generated: 05-Oct-2026 13:41:18 | Scope: Overdue assignments only | Total: 4309
A4: # | B4: Student Name | C4: Student Email | D4: Student Phone | E4: Course / Batch | F4: Subject / Duration | G4: Assignment | H4: Assigned Date | I4: Deadline | J4: Days Overdue | K4: Max Marks
A5: 1 | B5: Abhijeet Kankal | C5: abhijeetkankal2511@gmail.com | D5: +917972852259 | E5: PySpark | F5: 19-Nov-2024 To 07-Dec-2024 | G5: PySpark Assignment 1 | H5: 26-Nov-2024 | I5: 21-Dec-2024 | J5: 653
A6: 2 | B6: Abhishek Sutar | C6: abhisutar95@gmail.com | D6: +919545015530 | E6: PySpark | F6: 19-Nov-2024 To 07-Dec-2024 | G6: PySpark Assignment 1 | H6: 26-Nov-2024 | I6: 21-Dec-2024 | J6: 653
A7: 3 | B7: Aishwarya Kale | C7: aishwaryakale30@gmail.com | D7: +919028503189 | E7: PySpark | F7: 19-Nov-2024 To 07-Dec-2024 | G7: PySpark Assignment 1 | H7: 26-Nov-2024 | I7: 21-Dec-2024 | J7: 653
A8: 4 | B8: Ajit Komurlekar | C8: ajitkomurlekar@gmail.com | D8: +919757441754 | E8: PySpark | F8: 19-Nov-2024 To 07-Dec-2024 | G8: PySpark Assignment 1 | H8: 26-Nov-2024 | I8: 21-Dec-2024 | J8: 653
A9: 5 | B9: Akshay Dange | C9: akshayd7430@gmail.com | D9: +919028885783 | E9: PySpark | F9: 19-Nov-2024 To 07-Dec-2024 | G9: PySpark Assignment 1 | H9: 26-Nov-2024 | I9: 21-Dec-2024 | J9: 653
A10: 6 | B10: Akshay Deshbhratar | C10: asdeshbhratar@gmail.com | D10: +918888238622 | E10: PySpark | F10: 19-Nov-2024 To 07-Dec-2024 | G10: PySpark Assignment 1 | H10: 26-Nov-2024 | I10: 21-Dec-2024 | J10: 653
A11: 7 | B11: Ankita Sangle | C11: ankitasangle01@gmail.com | D11: +919834933532 | E11: PySpark | F11: 19-Nov-2024 To 07-Dec-2024 | G11: PySpark Assignment 1 | H11: 26-Nov-2024 | I11: 21-Dec-2024 | J11: 653
A12: 8 | B12: Biswajeet Singh | C12: bs.chandel97@gmail.com | D12: +919425686244 | E12: PySpark | F12: 19-Nov-2024 To 07-Dec-2024 | G12: PySpark Assignment 1 | H12: 26-Nov-2024 | I12: 21-Dec-2024 | J12: 653
A13: 9 | B13: Cyrus Masih | C13: masihcyrus10@gmail.com | D13: +919119432417 | E13: PySpark | F13: 19-Nov-2024 To 07-Dec-2024 | G13: PySpark Assignment 1 | H13: 26-Nov-2024 | I13: 21-Dec-2024 | J13: 653
A14: 10 | B14: Devendra Pataskar | C14: devdpat@gmail.com | D14: +919763975119 | E14: PySpark | F14: 19-Nov-2024 To 07-Dec-2024 | G14: PySpark Assignment 1 | H14: 26-Nov-2024 | I14: 21-Dec-2024 | J14: 653
A15: 11 | B15: Dhanashree Thakare | C15: dhanshreet21@gmail.com | D15: +919172157107 | E15: PySpark | F15: 19-Nov-2024 To 07-Dec-2024 | G15: PySpark Assignment 1 | H15: 26-Nov-2024 | I15: 21-Dec-2024 | J15: 653
A16: 12 | B16: Jyoti Pawar | C16: jyotipawar24823@gmail.com | D16: +919529149153 | E16: PySpark | F16: 19-Nov-2024 To 07-Dec-2024 | G16: PySpark Assignment 1 | H16: 26-Nov-2024 | I16: 21-Dec-2024 | J16: 653
... A40: 36 | B40: Yogita Khadke | C40: yogitakhadke48@gmail.com | D40: +918329099712 | E40: PySpark | F40: 19-Nov-2024 To 07-Dec-2024 | G40: PySpark Assignment 1 | H40: 26-Nov-2024 | I40: 21-Dec-2024 | J40: 653
A41: 37 | B41: Abhijeet Kankal | C41: abhijeetkankal2511@gmail.com | D41: +917972852259 | E41: Data Analyst (Power BI+MS Fabric) | F41: DA Apr 2024 | G41: Azure Assignment No 2 | H41: 10-Dec-2024 | I41: 23-Dec-2024 | J41: 651 | K41: 93
A42: 38 | B42: Ghanshyam Sadhu | C42: ghanshyamsadhu1975@gmail.com | D42: +918976130600 | E42: Data Analyst (Power BI+MS Fabric) | F42: DA Apr 2024 | G42: Azure Assignment No 2 | H42: 10-Dec-2024 | I42: 23-Dec-2024 | J42: 651 | K42: 93
A43: 39 | B43: Kajal Devkar | C43: devkarkajal77@gmail.com | D43: +918766930396 | E43: Data Analyst (Power BI+MS Fabric) | F43: DA Apr 2024 | G43: Azure Assignment No 2 | H43: 10-Dec-2024 | I43: 23-Dec-2024 | J43: 651 | K43: 93
A44: 40 | B44: Rameshwar Ingale | C44: rameshwar.ingale.7230@gmail.com | D44: +917447849559 | E44: Data Analyst (Power BI+MS Fabric) | F44: DA Apr 2024 | G44: Azure Assignment No 2 | H44: 10-Dec-2024 | I44: 23-Dec-2024 | J44: 651 | K44: 93
A45: 41 | B45: Rupali Mane | C45: manesrupali8@gmail.com | D45: +918080565806 | E45: Data Analyst (Power BI+MS Fabric) | F45: DA Apr 2024 | G45: Azure Assignment No 2 | H45: 10-Dec-2024 | I45: 23-Dec-2024 | J45: 651 | K45: 93
A46: 42 | B46: Swati Sonawane | C46: sonawane.swati21@gmail.com | D46: +919096438891 | E46: Data Analyst (Power BI+MS Fabric) | F46: DA Apr 2024 | G46: Azure Assignment No 2 | H46: 10-Dec-2024 | I46: 23-Dec-2024 | J46: 651 | K46: 93
A47: 43 | B47: Vishnu Mali | C47: vishnumali330443@gmail.com | D47: +9109923330443 | E47: Data Analyst (Power BI+MS Fabric) | F47: DA Apr 2024 | G47: Azure Assignment No 2 | H47: 10-Dec-2024 | I47: 23-Dec-2024 | J47: 651 | K47: 93
A48: 44 | B48: Abhishek Lodhi | C48: abhishekglodhi2001@gmail.com | D48: +918770413417 | E48: SQL | Python |Azure | F48: 10-Dec-2024 To 18-Jan-2025 | G48: T-SQL Assignment 2 | H48: 17-Dec-2024 | I48: 24-Dec-2024 | J48: 650 | K48: 20
A49: 45 | B49: Abhishek Raidas | C49: abhishek.raidas@gmail.com | D49: +919172948776 | E49: SQL | Python |Azure | F49: 10-Dec-2024 To 18-Jan-2025 | G49: T-SQL Assignment 2 | H49: 17-Dec-2024 | I49: 24-Dec-2024 | J49: 650 | K49: 20
A50: 46 | B50: Akshay Kale | C50: kaleakshay1297@gmail.com | D50: +917798480026 | E50: SQL | Python |Azure | F50: 10-Dec-2024 To 18-Jan-2025 | G50: T-SQL Assignment 2 | H50: 17-Dec-2024 | I50: 24-Dec-2024 | J50: 650 | K50: 20
A51: 47 | B51: Arati Sabane | C51: sabanearati96@gmail.com | D51: +919764879308 | E51: SQL | Python |Azure | F51: 10-Dec-2024 To 18-Jan-2025 | G51: T-SQL Assignment 2 | H51: 17-Dec-2024 | I51: 24-Dec-2024 | J51: 650 | K51: 20
A52: 48 | B52: Bhupen Bhosale | C52: bhupenbhosale96@gmail.com | D52: +918308123187 | E52: SQL | Python |Azure | F52: 10-Dec-2024 To 18-Jan-2025 | G52: T-SQL Assignment 2 | H52: 17-Dec-2024 | I52: 24-Dec-2024 | J52: 650 | K52: 20
... A246: 242 | B246: Yogesh Mangulkar | C246: yoghlearningcloud@gmail.com | D246: +919403018518 | E246: GCP | F246: 26-Nov-2024 To 21-May-2025 | G246: GCP Assignment No 2 | H246: 29-Jan-2025 | I246: 13-Feb-2025 | J246: 599 | K246: 60
A247: 243 | B247: Akshay Malviya | C247: malviyaakshay27@gmail.com | D247: +919325744590 | E247: SQL | Python | F247: 17-Feb-2025 To 10-Apr-2025 | G247: T-SQL Assignment 1 | H247: 02-Mar-2025 | I247: 09-Mar-2025 | J247: 575
A248: 244 | B248: Anuja Sisode | C248: anuja.s.shisode@gmail.com | D248: +919423738383 | E248: SQL | Python | F248: 17-Feb-2025 To 10-Apr-2025 | G248: T-SQL Assignment 1 | H248: 02-Mar-2025 | I248: 09-Mar-2025 | J248: 575
A249: 245 | B249: Ayush Atkari | C249: ayushatkari247@gmail.com | D249: +919022894473 | E249: SQL | Python | F249: 17-Feb-2025 To 10-Apr-2025 | G249: T-SQL Assignment 1 | H249: 02-Mar-2025 | I249: 09-Mar-2025 | J249: 575
A250: 246 | B250: Prashant Avhad | C250: avhadpr18@gmail.com | D250: +919309143115 | E250: SQL | Python | F250: 17-Feb-2025 To 10-Apr-2025 | G250: T-SQL Assignment 1 | H250: 02-Mar-2025 | I250: 09-Mar-2025 | J250: 575
A251: 247 | B251: Ruturaj Mane | C251: ruturajk.mane@gmail.com | D251: +917558450589 | E251: SQL | Python | F251: 17-Feb-2025 To 10-Apr-2025 | G251: T-SQL Assignment 1 | H251: 02-Mar-2025 | I251: 09-Mar-2025 | J251: 575
A252: 248 | B252: Sagar Gondane | C252: sagar.gondane12@gmail.com | D252: +917767861676 | E252: SQL | Python | F252: 17-Feb-2025 To 10-Apr-2025 | G252: T-SQL Assignment 1 | H252: 02-Mar-2025 | I252: 09-Mar-2025 | J252: 575
A253: 249 | B253: Sharda Thanage | C253: shardathanage38@gmail.com | D253: +919370359728 | E253: SQL | Python | F253: 17-Feb-2025 To 10-Apr-2025 | G253: T-SQL Assignment 1 | H253: 02-Mar-2025 | I253: 09-Mar-2025 | J253: 575
A254: 250 | B254: Swapnali Onkar | C254: swapzonkar@gmail.com | D254: +9108793575628 | E254: SQL | Python | F254: 17-Feb-2025 To 10-Apr-2025 | G254: T-SQL Assignment 1 | H254: 02-Mar-2025 | I254: 09-Mar-2025 | J254: 575
A255: 251 | B255: Vaibhav Khillari | C255: vaibhavkhilari123@gmail.com | D255: +917972134644 | E255: SQL | Python | F255: 17-Feb-2025 To 10-Apr-2025 | G255: T-SQL Assignment 1 | H255: 02-Mar-2025 | I255: 09-Mar-2025 | J255: 575
A256: 252 | B256: Akshay Malviya | C256: malviyaakshay27@gmail.com | D256: +919325744590 | E256: SQL | Python | F256: 17-Feb-2025 To 10-Apr-2025 | G256: T-SQL Assignment 2 | H256: 14-Mar-2025 | I256: 06-Apr-2025 | J256: 547
A257: 253 | B257: Anuja Sisode | C257: anuja.s.shisode@gmail.com | D257: +919423738383 | E257: SQL | Python | F257: 17-Feb-2025 To 10-Apr-2025 | G257: T-SQL Assignment 2 | H257: 14-Mar-2025 | I257: 06-Apr-2025 | J257: 547
...

Sheet Summary by Course
A1: Overdue Submissions — Summary by Course / Batch
A3: Course / Batch | B3: Overdue Count
A4: AI (GenAI • Agentic AI • ML) | B4: =COUNTIF('Overdue Submissions'!$E$5:$E$4313,A4)
A5: AWS | B5: =COUNTIF('Overdue Submissions'!$E$5:$E$4313,A5)
A6: Advance Excel And R | B6: =COUNTIF('Overdue Submissions'!$E$5:$E$4313,A6)
A7: Advanced Excel | R | B7: =COUNTIF('Overdue Submissions'!$E$5:$E$4313,A7)
A8: Advanced Excel | R | Tableau | B8: =COUNTIF('Overdue Submissions'!$E$5:$E$4313,A8)
A9: Advanced Python | PySpark | B9: =COUNTIF('Overdue Submissions'!$E$5:$E$4313,A9)
A10: Apache Airflow | B10: =COUNTIF('Overdue Submissions'!$E$5:$E$4313,A10)
A11: Azure | B11: =COUNTIF('Overdue Submissions'!$E$5:$E$4313,A11)
A12: Azure Project | B12: =COUNTIF('Overdue Submissions'!$E$5:$E$4313,A12)
A13: Azure Project - A | B13: =COUNTIF('Overdue Submissions'!$E$5:$E$4313,A13)
A14: Azure Project - B | B14: =COUNTIF('Overdue Submissions'!$E$5:$E$4313,A14)
A15: Core Advanced Python | B15: =COUNTIF('Overdue Submissions'!$E$5:$E$4313,A15)
... A35: Tableau | ChatGPT | B35: =COUNTIF('Overdue Submissions'!$E$5:$E$4313,A35)
A36: TOTAL | B36: =SUM(B4:B35)
